2017-12-14T12:15:26.613090+00:00 app[web.1]:     __import__(name)
2017-12-14T12:15:26.613090+00:00 app[web.1]:   File "/app/CandyLand/urls.py", line 25, in <module>
2017-12-14T12:15:26.613090+00:00 app[web.1]:     from settings.dev import MEDIA_ROOT
2017-12-14T12:15:26.613091+00:00 app[web.1]: ImportError: No module named dev
2017-12-14T12:15:26.613419+00:00 app[web.1]: Internal Server Error: /
2017-12-14T12:15:26.613420+00:00 app[web.1]: Traceback (most recent call last):
2017-12-14T12:15:26.613420+00:00 app[web.1]:   File "/app/.heroku/python/lib/python2.7/site-packages/django/core/handlers/exception.py", line 41, in inner
2017-12-14T12:15:26.613420+00:00 app[web.1]:     response = get_response(request)
2017-12-14T12:15:26.613421+00:00 app[web.1]:   File "/app/.heroku/python/lib/python2.7/site-packages/django/utils/deprecation.py", line 140, in __call__
2017-12-14T12:15:26.613421+00:00 app[web.1]:     response = self.get_response(request)
2017-12-14T12:15:26.613422+00:00 app[web.1]:   File "/app/.heroku/python/lib/python2.7/site-packages/django/core/handlers/exception.py", line 43, in inner
2017-12-14T12:15:26.613422+00:00 app[web.1]:     response = response_for_exception(request, exc)
2017-12-14T12:15:26.613422+00:00 app[web.1]:   File "/app/.heroku/python/lib/python2.7/site-packages/django/core/handlers/exception.py", line 93, in response_for_exception
2017-12-14T12:15:26.613423+00:00 app[web.1]:     response = handle_uncaught_exception(request, get_resolver(get_urlconf()), sys.exc_info())
2017-12-14T12:15:26.613423+00:00 app[web.1]:   File "/app/.heroku/python/lib/python2.7/site-packages/django/core/handlers/exception.py", line 142, in handle_uncaught_exception
2017-12-14T12:15:26.613424+00:00 app[web.1]:     callback, param_dict = resolver.resolve_error_handler(500)
2017-12-14T12:15:26.613424+00:00 app[web.1]:   File "/app/.heroku/python/lib/python2.7/site-packages/django/urls/resolvers.py", line 418, in resolve_error_handler
2017-12-14T12:15:26.613424+00:00 app[web.1]:     callback = getattr(self.urlconf_module, 'handler%s' % view_type, None)
2017-12-14T12:15:26.613425+00:00 app[web.1]:   File "/app/.heroku/python/lib/python2.7/site-packages/django/utils/functional.py", line 35, in __get__
2017-12-14T12:15:26.613425+00:00 app[web.1]:     res = instance.__dict__[self.name] = self.func(instance)
2017-12-14T12:15:26.613426+00:00 app[web.1]:   File "/app/.heroku/python/lib/python2.7/site-packages/django/urls/resolvers.py", line 398, in urlconf_module
2017-12-14T12:15:26.613426+00:00 app[web.1]:     return import_module(self.urlconf_name)
2017-12-14T12:15:26.613426+00:00 app[web.1]:   File "/app/.heroku/python/lib/python2.7/importlib/__init__.py", line 37, in import_module
2017-12-14T12:15:26.613427+00:00 app[web.1]:     __import__(name)
2017-12-14T12:15:26.613427+00:00 app[web.1]:   File "/app/CandyLand/urls.py", line 25, in <module>
2017-12-14T12:15:26.613427+00:00 app[web.1]:     from settings.dev import MEDIA_ROOT
2017-12-14T12:15:26.613428+00:00 app[web.1]: ImportError: No module named dev
2017-12-14T12:15:26.613903+00:00 app[web.1]: Internal Server Error: /
2017-12-14T12:15:26.613903+00:00 app[web.1]: Traceback (most recent call last):
2017-12-14T12:15:26.613904+00:00 app[web.1]:   File "/app/.heroku/python/lib/python2.7/site-packages/django/core/handlers/exception.py", line 41, in inner
2017-12-14T12:15:26.613904+00:00 app[web.1]:     response = get_response(request)
2017-12-14T12:15:26.613905+00:00 app[web.1]:   File "/app/.heroku/python/lib/python2.7/site-packages/django/utils/deprecation.py", line 140, in __call__
2017-12-14T12:15:26.613905+00:00 app[web.1]:     response = self.get_response(request)
2017-12-14T12:15:26.613905+00:00 app[web.1]:   File "/app/.heroku/python/lib/python2.7/site-packages/django/core/handlers/exception.py", line 43, in inner
2017-12-14T12:15:26.613906+00:00 app[web.1]:     response = response_for_exception(request, exc)
2017-12-14T12:15:26.613906+00:00 app[web.1]:   File "/app/.heroku/python/lib/python2.7/site-packages/django/core/handlers/exception.py", line 93, in response_for_exception
2017-12-14T12:15:26.613907+00:00 app[web.1]:     response = handle_uncaught_exception(request, get_resolver(get_urlconf()), sys.exc_info())
2017-12-14T12:15:26.613907+00:00 app[web.1]:   File "/app/.heroku/python/lib/python2.7/site-packages/django/core/handlers/exception.py", line 142, in handle_uncaught_exception
2017-12-14T12:15:26.613907+00:00 app[web.1]:     callback, param_dict = resolver.resolve_error_handler(500)
2017-12-14T12:15:26.613908+00:00 app[web.1]:   File "/app/.heroku/python/lib/python2.7/site-packages/django/urls/resolvers.py", line 418, in resolve_error_handler
2017-12-14T12:15:26.613908+00:00 app[web.1]:     callback = getattr(self.urlconf_module, 'handler%s' % view_type, None)
2017-12-14T12:15:26.613909+00:00 app[web.1]:   File "/app/.heroku/python/lib/python2.7/site-packages/django/utils/functional.py", line 35, in __get__
2017-12-14T12:15:26.613909+00:00 app[web.1]:     res = instance.__dict__[self.name] = self.func(instance)
2017-12-14T12:15:26.613909+00:00 app[web.1]:   File "/app/.heroku/python/lib/python2.7/site-packages/django/urls/resolvers.py", line 398, in urlconf_module
2017-12-14T12:15:26.613910+00:00 app[web.1]:     return import_module(self.urlconf_name)
2017-12-14T12:15:26.613910+00:00 app[web.1]:   File "/app/.heroku/python/lib/python2.7/importlib/__init__.py", line 37, in import_module
2017-12-14T12:15:26.613910+00:00 app[web.1]:     __import__(name)
2017-12-14T12:15:26.613911+00:00 app[web.1]:   File "/app/CandyLand/urls.py", line 25, in <module>
2017-12-14T12:15:26.613911+00:00 app[web.1]:     from settings.dev import MEDIA_ROOT
2017-12-14T12:15:26.613911+00:00 app[web.1]: ImportError: No module named dev
2017-12-14T12:15:26.614264+00:00 app[web.1]: Internal Server Error: /
2017-12-14T12:15:26.614265+00:00 app[web.1]: Traceback (most recent call last):
2017-12-14T12:15:26.614265+00:00 app[web.1]:   File "/app/.heroku/python/lib/python2.7/site-packages/django/core/handlers/exception.py", line 41, in inner
2017-12-14T12:15:26.614266+00:00 app[web.1]:     response = get_response(request)
2017-12-14T12:15:26.614266+00:00 app[web.1]:   File "/app/.heroku/python/lib/python2.7/site-packages/django/utils/deprecation.py", line 140, in __call__
2017-12-14T12:15:26.614266+00:00 app[web.1]:     response = self.get_response(request)
2017-12-14T12:15:26.614267+00:00 app[web.1]:   File "/app/.heroku/python/lib/python2.7/site-packages/django/core/handlers/exception.py", line 43, in inner
2017-12-14T12:15:26.614267+00:00 app[web.1]:     response = response_for_exception(request, exc)
2017-12-14T12:15:26.614268+00:00 app[web.1]:   File "/app/.heroku/python/lib/python2.7/site-packages/django/core/handlers/exception.py", line 93, in response_for_exception
2017-12-14T12:15:26.614268+00:00 app[web.1]:     response = handle_uncaught_exception(request, get_resolver(get_urlconf()), sys.exc_info())
2017-12-14T12:15:26.614268+00:00 app[web.1]:   File "/app/.heroku/python/lib/python2.7/site-packages/django/core/handlers/exception.py", line 142, in handle_uncaught_exception
2017-12-14T12:15:26.614269+00:00 app[web.1]:     callback, param_dict = resolver.resolve_error_handler(500)
2017-12-14T12:15:26.614277+00:00 app[web.1]:   File "/app/.heroku/python/lib/python2.7/site-packages/django/urls/resolvers.py", line 418, in resolve_error_handler
2017-12-14T12:15:26.614277+00:00 app[web.1]:     callback = getattr(self.urlconf_module, 'handler%s' % view_type, None)
2017-12-14T12:15:26.614278+00:00 app[web.1]:   File "/app/.heroku/python/lib/python2.7/site-packages/django/utils/functional.py", line 35, in __get__
2017-12-14T12:15:26.614278+00:00 app[web.1]:     res = instance.__dict__[self.name] = self.func(instance)
2017-12-14T12:15:26.614279+00:00 app[web.1]:   File "/app/.heroku/python/lib/python2.7/site-packages/django/urls/resolvers.py", line 398, in urlconf_module
2017-12-14T12:15:26.614279+00:00 app[web.1]:     return import_module(self.urlconf_name)
2017-12-14T12:15:26.614279+00:00 app[web.1]:   File "/app/.heroku/python/lib/python2.7/importlib/__init__.py", line 37, in import_module
2017-12-14T12:15:26.614280+00:00 app[web.1]:     __import__(name)
2017-12-14T12:15:26.614280+00:00 app[web.1]:   File "/app/CandyLand/urls.py", line 25, in <module>
2017-12-14T12:15:26.614280+00:00 app[web.1]:     from settings.dev import MEDIA_ROOT
2017-12-14T12:15:26.614281+00:00 app[web.1]: ImportError: No module named dev
2017-12-14T12:15:26.614855+00:00 app[web.1]: [2017-12-14 12:15:26 +0000] [9] [ERROR] Error handling request /
2017-12-14T12:15:26.614856+00:00 app[web.1]: Traceback (most recent call last):
2017-12-14T12:15:26.614856+00:00 app[web.1]:   File "/app/.heroku/python/lib/python2.7/site-packages/gunicorn/workers/sync.py", line 130, in handle
2017-12-14T12:15:26.614856+00:00 app[web.1]:     self.handle_request(listener, req, client, addr)
2017-12-14T12:15:26.614857+00:00 app[web.1]:   File "/app/.heroku/python/lib/python2.7/site-packages/gunicorn/workers/sync.py", line 171, in handle_request
2017-12-14T12:15:26.614857+00:00 app[web.1]:     respiter = self.wsgi(environ, resp.start_response)
2017-12-14T12:15:26.614858+00:00 app[web.1]:   File "/app/.heroku/python/lib/python2.7/site-packages/django/core/handlers/wsgi.py", line 157, in __call__
2017-12-14T12:15:26.614858+00:00 app[web.1]:     response = self.get_response(request)
2017-12-14T12:15:26.614858+00:00 app[web.1]:   File "/app/.heroku/python/lib/python2.7/site-packages/django/core/handlers/base.py", line 124, in get_response
2017-12-14T12:15:26.614859+00:00 app[web.1]:     response = self._middleware_chain(request)
2017-12-14T12:15:26.614859+00:00 app[web.1]:   File "/app/.heroku/python/lib/python2.7/site-packages/django/core/handlers/exception.py", line 43, in inner
2017-12-14T12:15:26.614859+00:00 app[web.1]:     response = response_for_exception(request, exc)
2017-12-14T12:15:26.614860+00:00 app[web.1]:   File "/app/.heroku/python/lib/python2.7/site-packages/django/core/handlers/exception.py", line 93, in response_for_exception
2017-12-14T12:15:26.614860+00:00 app[web.1]:     response = handle_uncaught_exception(request, get_resolver(get_urlconf()), sys.exc_info())
2017-12-14T12:15:26.614861+00:00 app[web.1]:   File "/app/.heroku/python/lib/python2.7/site-packages/django/core/handlers/exception.py", line 142, in handle_uncaught_exception
2017-12-14T12:15:26.614861+00:00 app[web.1]:     callback, param_dict = resolver.resolve_error_handler(500)
2017-12-14T12:15:26.614862+00:00 app[web.1]:   File "/app/.heroku/python/lib/python2.7/site-packages/django/urls/resolvers.py", line 418, in resolve_error_handler
2017-12-14T12:15:26.614862+00:00 app[web.1]:     callback = getattr(self.urlconf_module, 'handler%s' % view_type, None)
2017-12-14T12:15:26.614863+00:00 app[web.1]:   File "/app/.heroku/python/lib/python2.7/site-packages/django/utils/functional.py", line 35, in __get__
2017-12-14T12:15:26.614863+00:00 app[web.1]:     res = instance.__dict__[self.name] = self.func(instance)
2017-12-14T12:15:26.614863+00:00 app[web.1]:   File "/app/.heroku/python/lib/python2.7/site-packages/django/urls/resolvers.py", line 398, in urlconf_module
2017-12-14T12:15:26.614864+00:00 app[web.1]:     return import_module(self.urlconf_name)
2017-12-14T12:15:26.614864+00:00 app[web.1]:   File "/app/.heroku/python/lib/python2.7/importlib/__init__.py", line 37, in import_module
2017-12-14T12:15:26.614864+00:00 app[web.1]:     __import__(name)
2017-12-14T12:15:26.614865+00:00 app[web.1]:   File "/app/CandyLand/urls.py", line 25, in <module>
2017-12-14T12:15:26.614865+00:00 app[web.1]:     from settings.dev import MEDIA_ROOT
2017-12-14T12:15:26.614865+00:00 app[web.1]: ImportError: No module named dev
2017-12-14T12:15:26.629341+00:00 heroku[router]: at=info method=GET path="/" host=candyland2.herokuapp.com request_id=0ef0e31b-6766-45f5-96ed-4d83a8c429d9 fwd="2.25.81.139" dyno=web.1 connect=0ms service=31ms status=500 bytes=244 protocol=https
